Workbook

Sheet Sheet1
B1: Rent | D1: HDB Resale | F1: Condo | I1: Workings
B2: Outflow | C2: Equity | D2: Outflow | E2: Equity | F2: Outflow | G2: Equity | H2: Condo milestone / note | I2: HDB loan balance | J2: HDB interest | K2: Condo disbursement | L2: Condo opening bal. | M2: Condo interest | N2: Condo loan balance
A3: 46296 | B3: =IF(A3<Assumptions!$B$4,Assumptions!$B$3,Assumptions!$B$5) -> 2000 | C3: 0 | D3: =IF(A3=Assumptions!$B$14,Assumptions!$B$13,IF(AND(A3>Assumptions!$B$14,N(I2)>0.5),Assumptions!$B$18,0)) -> 0 | E3: =IF(A3=Assumptions!$B$14,Assumptions!$B$10,IF(A3>Assumptions!$B$14,D3-J3,0)) -> 0 | F3: =IF(A3=Assumptions!$B$25,Assumptions!$B$24,0)+IF(L3>0,PMT(Assumptions!$B$26/12,(Assumptions!$B$27*12+1-((YEAR(A3)-YEAR(Assumptions!$B$33))*12+MONTH(A3)-MONTH(Assumptions!$B$33))),-L3),0) -> 565000 | G3: =IF(A3=Assumptions!$B$25,Assumptions!$B$23,0)+IF(L3>0,PMT(Assumptions!$B$26/12,(Assumptions!$B$27*12+1-((YEAR(A3)-YEAR(Assumptions!$B$33))*12+MONTH(A3)-MONTH(Assumptions!$B$33))),-L3),0)-M3 -> 495000 | H3: =IF(A3=Assumptions!$B$25,"Condo: OTP + S&P + 25% equity paid",IF(A3=Assumptions!$B$14,"HDB: completion, downpayment paid",IFERROR("Condo: "&INDEX(Assumptions!$A$33:$A$40,MATCH(A3,Assumptions!$B$33:$B$40,0)),""))) -> Condo: OTP + S&P + 25% equity paid | I3: =IF(A3=Assumptions!$B$14,Assumptions!$B$17,IF(A3>Assumptions!$B$14,N(I2)-E3,0)) -> 0 | J3: =IF(A3>Assumptions!$B$14,N(I2)*Assumptions!$B$15/12,0) -> 0 | K3: =SUMIFS(Assumptions!$D$33:$D$40,Assumptions!$B$33:$B$40,A3) -> 0 | L3: =N(N2) -> 0 | M3: =L3*Assumptions!$B$26/12 -> 0 | N3: =L3+K3-(IF(L3>0,PMT(Assumptions!$B$26/12,(Assumptions!$B$27*12+1-((YEAR(A3)-YEAR(Assumptions!$B$33))*12+MONTH(A3)-MONTH(Assumptions!$B$33))),-L3),0)-M3) -> 0
A4: 46327 | B4: =IF(A4<Assumptions!$B$4,Assumptions!$B$3,Assumptions!$B$5) -> 2000 | C4: 0 | D4: =IF(A4=Assumptions!$B$14,Assumptions!$B$13,IF(AND(A4>Assumptions!$B$14,N(I3)>0.5),Assumptions!$B$18,0)) -> 0 | E4: =IF(A4=Assumptions!$B$14,Assumptions!$B$10,IF(A4>Assumptions!$B$14,D4-J4,0)) -> 0 | F4: =IF(A4=Assumptions!$B$25,Assumptions!$B$24,0)+IF(L4>0,PMT(Assumptions!$B$26/12,(Assumptions!$B$27*12+1-((YEAR(A4)-YEAR(Assumptions!$B$33))*12+MONTH(A4)-MONTH(Assumptions!$B$33))),-L4),0) -> 0 | G4: =IF(A4=Assumptions!$B$25,Assumptions!$B$23,0)+IF(L4>0,PMT(Assumptions!$B$26/12,(Assumptions!$B$27*12+1-((YEAR(A4)-YEAR(Assumptions!$B$33))*12+MONTH(A4)-MONTH(Assumptions!$B$33))),-L4),0)-M4 -> 0 | H4: =IF(A4=Assumptions!$B$25,"Condo: OTP + S&P + 25% equity paid",IF(A4=Assumptions!$B$14,"HDB: completion, downpayment paid",IFERROR("Condo: "&INDEX(Assumptions!$A$33:$A$40,MATCH(A4,Assumptions!$B$33:$B$40,0)),""))) | I4: =IF(A4=Assumptions!$B$14,Assumptions!$B$17,IF(A4>Assumptions!$B$14,N(I3)-E4,0)) -> 0 | J4: =IF(A4>Assumptions!$B$14,N(I3)*Assumptions!$B$15/12,0) -> 0 | K4: =SUMIFS(Assumptions!$D$33:$D$40,Assumptions!$B$33:$B$40,A4) -> 0 | L4: =N(N3) -> 0 | M4: =L4*Assumptions!$B$26/12 -> 0 | N4: =L4+K4-(IF(L4>0,PMT(Assumptions!$B$26/12,(Assumptions!$B$27*12+1-((YEAR(A4)-YEAR(Assumptions!$B$33))*12+MONTH(A4)-MONTH(Assumptions!$B$33))),-L4),0)-M4) -> 0
A5: 46357 | B5: =IF(A5<Assumptions!$B$4,Assumptions!$B$3,Assumptions!$B$5) -> 2000 | C5: 0 | D5: =IF(A5=Assumptions!$B$14,Assumptions!$B$13,IF(AND(A5>Assumptions!$B$14,N(I4)>0.5),Assumptions!$B$18,0)) -> 0 | E5: =IF(A5=Assumptions!$B$14,Assumptions!$B$10,IF(A5>Assumptions!$B$14,D5-J5,0)) -> 0 | F5: =IF(A5=Assumptions!$B$25,Assumptions!$B$24,0)+IF(L5>0,PMT(Assumptions!$B$26/12,(Assumptions!$B$27*12+1-((YEAR(A5)-YEAR(Assumptions!$B$33))*12+MONTH(A5)-MONTH(Assumptions!$B$33))),-L5),0) -> 0 | G5: =IF(A5=Assumptions!$B$25,Assumptions!$B$23,0)+IF(L5>0,PMT(Assumptions!$B$26/12,(Assumptions!$B$27*12+1-((YEAR(A5)-YEAR(Assumptions!$B$33))*12+MONTH(A5)-MONTH(Assumptions!$B$33))),-L5),0)-M5 -> 0 | H5: =IF(A5=Assumptions!$B$25,"Condo: OTP + S&P + 25% equity paid",IF(A5=Assumptions!$B$14,"HDB: completion, downpayment paid",IFERROR("Condo: "&INDEX(Assumptions!$A$33:$A$40,MATCH(A5,Assumptions!$B$33:$B$40,0)),""))) | I5: =IF(A5=Assumptions!$B$14,Assumptions!$B$17,IF(A5>Assumptions!$B$14,N(I4)-E5,0)) -> 0 | J5: =IF(A5>Assumptions!$B$14,N(I4)*Assumptions!$B$15/12,0) -> 0 | K5: =SUMIFS(Assumptions!$D$33:$D$40,Assumptions!$B$33:$B$40,A5) -> 0 | L5: =N(N4) -> 0 | M5: =L5*Assumptions!$B$26/12 -> 0 | N5: =L5+K5-(IF(L5>0,PMT(Assumptions!$B$26/12,(Assumptions!$B$27*12+1-((YEAR(A5)-YEAR(Assumptions!$B$33))*12+MONTH(A5)-MONTH(Assumptions!$B$33))),-L5),0)-M5) -> 0
A6: 46388 | B6: =IF(A6<Assumptions!$B$4,Assumptions!$B$3,Assumptions!$B$5) -> 2000 | C6: 0 | D6: =IF(A6=Assumptions!$B$14,Assumptions!$B$13,IF(AND(A6>Assumptions!$B$14,N(I5)>0.5),Assumptions!$B$18,0)) -> 249600 | E6: =IF(A6=Assumptions!$B$14,Assumptions!$B$10,IF(A6>Assumptions!$B$14,D6-J6,0)) -> 225000 | F6: =IF(A6=Assumptions!$B$25,Assumptions!$B$24,0)+IF(L6>0,PMT(Assumptions!$B$26/12,(Assumptions!$B$27*12+1-((YEAR(A6)-YEAR(Assumptions!$B$33))*12+MONTH(A6)-MONTH(Assumptions!$B$33))),-L6),0) -> 0 | G6: =IF(A6=Assumptions!$B$25,Assumptions!$B$23,0)+IF(L6>0,PMT(Assumptions!$B$26/12,(Assumptions!$B$27*12+1-((YEAR(A6)-YEAR(Assumptions!$B$33))*12+MONTH(A6)-MONTH(Assumptions!$B$33))),-L6),0)-M6 -> 0 | H6: =IF(A6=Assumptions!$B$25,"Condo: OTP + S&P + 25% equity paid",IF(A6=Assumptions!$B$14,"HDB: completion, downpayment paid",IFERROR("Condo: "&INDEX(Assumptions!$A$33:$A$40,MATCH(A6,Assumptions!$B$33:$B$40,0)),""))) -> HDB: completion, downpayment paid | I6: =IF(A6=Assumptions!$B$14,Assumptions!$B$17,IF(A6>Assumptions!$B$14,N(I5)-E6,0)) -> 675000 | J6: =IF(A6>Assumptions!$B$14,N(I5)*Assumptions!$B$15/12,0) -> 0 | K6: =SUMIFS(Assumptions!$D$33:$D$40,Assumptions!$B$33:$B$40,A6) -> 99000 | L6: =N(N5) -> 0 | M6: =L6*Assumptions!$B$26/12 -> 0 | N6: =L6+K6-(IF(L6>0,PMT(Assumptions!$B$26/12,(Assumptions!$B$27*12+1-((YEAR(A6)-YEAR(Assumptions!$B$33))*12+MONTH(A6)-MONTH(Assumptions!$B$33))),-L6),0)-M6) -> 99000
A7: 46419 | B7: =IF(A7<Assumptions!$B$4,Assumptions!$B$3,Assumptions!$B$5) -> 2000 | C7: 0 | D7: =IF(A7=Assumptions!$B$14,Assumptions!$B$13,IF(AND(A7>Assumptions!$B$14,N(I6)>0.5),Assumptions!$B$18,0)) -> 3062.2692 | E7: =IF(A7=Assumptions!$B$14,Assumptions!$B$10,IF(A7>Assumptions!$B$14,D7-J7,0)) -> 1599.7692 | F7: =IF(A7=Assumptions!$B$25,Assumptions!$B$24,0)+IF(L7>0,PMT(Assumptions!$B$26/12,(Assumptions!$B$27*12+1-((YEAR(A7)-YEAR(Assumptions!$B$33))*12+MONTH(A7)-MONTH(Assumptions!$B$33))),-L7),0) -> 341.66901 | G7: =IF(A7=Assumptions!$B$25,Assumptions!$B$23,0)+IF(L7>0,PMT(Assumptions!$B$26/12,(Assumptions!$B$27*12+1-((YEAR(A7)-YEAR(Assumptions!$B$33))*12+MONTH(A7)-MONTH(Assumptions!$B$33))),-L7),0)-M7 -> 217.91901 | H7: =IF(A7=Assumptions!$B$25,"Condo: OTP + S&P + 25% equity paid",IF(A7=Assumptions!$B$14,"HDB: completion, downpayment paid",IFERROR("Condo: "&INDEX(Assumptions!$A$33:$A$40,MATCH(A7,Assumptions!$B$33:$B$40,0)),""))) | I7: =IF(A7=Assumptions!$B$14,Assumptions!$B$17,IF(A7>Assumptions!$B$14,N(I6)-E7,0)) -> 673400.23 | J7: =IF(A7>Assumptions!$B$14,N(I6)*Assumptions!$B$15/12,0) -> 1462.5 | K7: =SUMIFS(Assumptions!$D$33:$D$40,Assumptions!$B$33:$B$40,A7) -> 0 | L7: =N(N6) -> 99000 | M7: =L7*Assumptions!$B$26/12 -> 123.75 | N7: =L7+K7-(IF(L7>0,PMT(Assumptions!$B$26/12,(Assumptions!$B$27*12+1-((YEAR(A7)-YEAR(Assumptions!$B$33))*12+MONTH(A7)-MONTH(Assumptions!$B$33))),-L7),0)-M7) -> 98782.081
A8: 46447 | B8: =IF(A8<Assumptions!$B$4,Assumptions!$B$3,Assumptions!$B$5) -> 2000 | C8: 0 | D8: =IF(A8=Assumptions!$B$14,Assumptions!$B$13,IF(AND(A8>Assumptions!$B$14,N(I7)>0.5),Assumptions!$B$18,0)) -> 3062.2692 | E8: =IF(A8=Assumptions!$B$14,Assumptions!$B$10,IF(A8>Assumptions!$B$14,D8-J8,0)) -> 1603.2353 | F8: =IF(A8=Assumptions!$B$25,Assumptions!$B$24,0)+IF(L8>0,PMT(Assumptions!$B$26/12,(Assumptions!$B$27*12+1-((YEAR(A8)-YEAR(Assumptions!$B$33))*12+MONTH(A8)-MONTH(Assumptions!$B$33))),-L8),0) -> 341.66901 | G8: =IF(A8=Assumptions!$B$25,Assumptions!$B$23,0)+IF(L8>0,PMT(Assumptions!$B$26/12,(Assumptions!$B$27*12+1-((YEAR(A8)-YEAR(Assumptions!$B$33))*12+MONTH(A8)-MONTH(Assumptions!$B$33))),-L8),0)-M8 -> 218.19141 | H8: =IF(A8=Assumptions!$B$25,"Condo: OTP + S&P + 25% equity paid",IF(A8=Assumptions!$B$14,"HDB: completion, downpayment paid",IFERROR("Condo: "&INDEX(Assumptions!$A$33:$A$40,MATCH(A8,Assumptions!$B$33:$B$40,0)),""))) | I8: =IF(A8=Assumptions!$B$14,Assumptions!$B$17,IF(A8>Assumptions!$B$14,N(I7)-E8,0)) -> 671797 | J8: =IF(A8>Assumptions!$B$14,N(I7)*Assumptions!$B$15/12,0) -> 1459.0338 | K8: =SUMIFS(Assumptions!$D$33:$D$40,Assumptions!$B$33:$B$40,A8) -> 0 | L8: =N(N7) -> 98782.081 | M8: =L8*Assumptions!$B$26/12 -> 123.4776 | N8: =L8+K8-(IF(L8>0,PMT(Assumptions!$B$26/12,(Assumptions!$B$27*12+1-((YEAR(A8)-YEAR(Assumptions!$B$33))*12+MONTH(A8)-MONTH(Assumptions!$B$33))),-L8),0)-M8) -> 98563.89
A9: 46478 | B9: =IF(A9<Assumptions!$B$4,Assumptions!$B$3,Assumptions!$B$5) -> 2000 | C9: 0 | D9: =IF(A9=Assumptions!$B$14,Assumptions!$B$13,IF(AND(A9>Assumptions!$B$14,N(I8)>0.5),Assumptions!$B$18,0)) -> 3062.2692 | E9: =IF(A9=Assumptions!$B$14,Assumptions!$B$10,IF(A9>Assumptions!$B$14,D9-J9,0)) -> 1606.709 | F9: =IF(A9=Assumptions!$B$25,Assumptions!$B$24,0)+IF(L9>0,PMT(Assumptions!$B$26/12,(Assumptions!$B$27*12+1-((YEAR(A9)-YEAR(Assumptions!$B$33))*12+MONTH(A9)-MONTH(Assumptions!$B$33))),-L9),0) -> 341.66901 | G9: =IF(A9=Assumptions!$B$25,Assumptions!$B$23,0)+IF(L9>0,PMT(Assumptions!$B$26/12,(Assumptions!$B$27*12+1-((YEAR(A9)-YEAR(Assumptions!$B$33))*12+MONTH(A9)-MONTH(Assumptions!$B$33))),-L9),0)-M9 -> 218.46415 | H9: =IF(A9=Assumptions!$B$25,"Condo: OTP + S&P + 25% equity paid",IF(A9=Assumptions!$B$14,"HDB: completion, downpayment paid",IFERROR("Condo: "&INDEX(Assumptions!$A$33:$A$40,MATCH(A9,Assumptions!$B$33:$B$40,0)),""))) | I9: =IF(A9=Assumptions!$B$14,Assumptions!$B$17,IF(A9>Assumptions!$B$14,N(I8)-E9,0)) -> 670190.29 | J9: =IF(A9>Assumptions!$B$14,N(I8)*Assumptions!$B$15/12,0) -> 1455.5602 | K9: =SUMIFS(Assumptions!$D$33:$D$40,Assumptions!$B$33:$B$40,A9) -> 0 | L9: =N(N8) -> 98563.89 | M9: =L9*Assumptions!$B$26/12 -> 123.20486 | N9: =L9+K9-(IF(L9>0,PMT(Assumptions!$B$26/12,(Assumptions!$B$27*12+1-((YEAR(A9)-YEAR(Assumptions!$B$33))*12+MONTH(A9)-MONTH(Assumptions!$B$33))),-L9),0)-M9) -> 98345.425
A10: 46508 | B10: =IF(A10<Assumptions!$B$4,Assumptions!$B$3,Assumptions!$B$5) -> 2000 | C10: 0 | D10: =IF(A10=Assumptions!$B$14,Assumptions!$B$13,IF(AND(A10>Assumptions!$B$14,N(I9)>0.5),Assumptions!$B$18,0)) -> 3062.2692 | E10: =IF(A10=Assumptions!$B$14,Assumptions!$B$10,IF(A10>Assumptions!$B$14,D10-J10,0)) -> 1610.1902 | F10: =IF(A10=Assumptions!$B$25,Assumptions!$B$24,0)+IF(L10>0,PMT(Assumptions!$B$26/12,(Assumptions!$B$27*12+1-((YEAR(A10)-YEAR(Assumptions!$B$33))*12+MONTH(A10)-MONTH(Assumptions!$B$33))),-L10),0) -> 341.66901 | G10: =IF(A10=Assumptions!$B$25,Assumptions!$B$23,0)+IF(L10>0,PMT(Assumptions!$B$26/12,(Assumptions!$B$27*12+1-((YEAR(A10)-YEAR(Assumptions!$B$33))*12+MONTH(A10)-MONTH(Assumptions!$B$33))),-L10),0)-M10 -> 218.73723 | H10: =IF(A10=Assumptions!$B$25,"Condo: OTP + S&P + 25% equity paid",IF(A10=Assumptions!$B$14,"HDB: completion, downpayment paid",IFERROR("Condo: "&INDEX(Assumptions!$A$33:$A$40,MATCH(A10,Assumptions!$B$33:$B$40,0)),""))) | I10: =IF(A10=Assumptions!$B$14,Assumptions!$B$17,IF(A10>Assumptions!$B$14,N(I9)-E10,0)) -> 668580.1 | J10: =IF(A10>Assumptions!$B$14,N(I9)*Assumptions!$B$15/12,0) -> 1452.079 | K10: =SUMIFS(Assumptions!$D$33:$D$40,Assumptions!$B$33:$B$40,A10) -> 0 | L10: =N(N9) -> 98345.425 | M10: =L10*Assumptions!$B$26/12 -> 122.93178 | N10: =L10+K10-(IF(L10>0,PMT(Assumptions!$B$26/12,(Assumptions!$B$27*12+1-((YEAR(A10)-YEAR(Assumptions!$B$33))*12+MONTH(A10)-MONTH(Assumptions!$B$33))),-L10),0)-M10) -> 98126.688
A11: 46539 | B11: =IF(A11<Assumptions!$B$4,Assumptions!$B$3,Assumptions!$B$5) -> 2000 | C11: 0 | D11: =IF(A11=Assumptions!$B$14,Assumptions!$B$13,IF(AND(A11>Assumptions!$B$14,N(I10)>0.5),Assumptions!$B$18,0)) -> 3062.2692 | E11: =IF(A11=Assumptions!$B$14,Assumptions!$B$10,IF(A11>Assumptions!$B$14,D11-J11,0)) -> 1613.679 | F11: =IF(A11=Assumptions!$B$25,Assumptions!$B$24,0)+IF(L11>0,PMT(Assumptions!$B$26/12,(Assumptions!$B$27*12+1-((YEAR(A11)-YEAR(Assumptions!$B$33))*12+MONTH(A11)-MONTH(Assumptions!$B$33))),-L11),0) -> 341.66901 | G11: =IF(A11=Assumptions!$B$25,Assumptions!$B$23,0)+IF(L11>0,PMT(Assumptions!$B$26/12,(Assumptions!$B$27*12+1-((YEAR(A11)-YEAR(Assumptions!$B$33))*12+MONTH(A11)-MONTH(Assumptions!$B$33))),-L11),0)-M11 -> 219.01065 | H11: =IF(A11=Assumptions!$B$25,"Condo: OTP + S&P + 25% equity paid",IF(A11=Assumptions!$B$14,"HDB: completion, downpayment paid",IFERROR("Condo: "&INDEX(Assumptions!$A$33:$A$40,MATCH(A11,Assumptions!$B$33:$B$40,0)),""))) | I11: =IF(A11=Assumptions!$B$14,Assumptions!$B$17,IF(A11>Assumptions!$B$14,N(I10)-E11,0)) -> 666966.42 | J11: =IF(A11>Assumptions!$B$14,N(I10)*Assumptions!$B$15/12,0) -> 1448.5902 | K11: =SUMIFS(Assumptions!$D$33:$D$40,Assumptions!$B$33:$B$40,A11) -> 0 | L11: =N(N10) -> 98126.688 | M11: =L11*Assumptions!$B$26/12 -> 122.65836 | N11: =L11+K11-(IF(L11>0,PMT(Assumptions!$B$26/12,(Assumptions!$B$27*12+1-((YEAR(A11)-YEAR(Assumptions!$B$33))*12+MONTH(A11)-MONTH(Assumptions!$B$33))),-L11),0)-M11) -> 97907.678
A12: 46569 | B12: =IF(A12<Assumptions!$B$4,Assumptions!$B$3,Assumptions!$B$5) -> 2000 | C12: 0 | D12: =IF(A12=Assumptions!$B$14,Assumptions!$B$13,IF(AND(A12>Assumptions!$B$14,N(I11)>0.5),Assumptions!$B$18,0)) -> 3062.2692 | E12: =IF(A12=Assumptions!$B$14,Assumptions!$B$10,IF(A12>Assumptions!$B$14,D12-J12,0)) -> 1617.1753 | F12: =IF(A12=Assumptions!$B$25,Assumptions!$B$24,0)+IF(L12>0,PMT(Assumptions!$B$26/12,(Assumptions!$B$27*12+1-((YEAR(A12)-YEAR(Assumptions!$B$33))*12+MONTH(A12)-MONTH(Assumptions!$B$33))),-L12),0) -> 341.66901 | G12: =IF(A12=Assumptions!$B$25,Assumptions!$B$23,0)+IF(L12>0,PMT(Assumptions!$B$26/12,(Assumptions!$B$27*12+1-((YEAR(A12)-YEAR(Assumptions!$B$33))*12+MONTH(A12)-MONTH(Assumptions!$B$33))),-L12),0)-M12 -> 219.28441 | H12: =IF(A12=Assumptions!$B$25,"Condo: OTP + S&P + 25% equity paid",IF(A12=Assumptions!$B$14,"HDB: completion, downpayment paid",IFERROR("Condo: "&INDEX(Assumptions!$A$33:$A$40,MATCH(A12,Assumptions!$B$33:$B$40,0)),""))) | I12: =IF(A12=Assumptions!$B$14,Assumptions!$B$17,IF(A12>Assumptions!$B$14,N(I11)-E12,0)) -> 665349.24 | J12: =IF(A12>Assumptions!$B$14,N(I11)*Assumptions!$B$15/12,0) -> 1445.0939 | K12: =SUMIFS(Assumptions!$D$33:$D$40,Assumptions!$B$33:$B$40,A12) -> 0 | L12: =N(N11) -> 97907.678 | M12: =L12*Assumptions!$B$26/12 -> 122.3846 | N12: =L12+K12-(IF(L12>0,PMT(Assumptions!$B$26/12,(Assumptions!$B$27*12+1-((YEAR(A12)-YEAR(Assumptions!$B$33))*12+MONTH(A12)-MONTH(Assumptions!$B$33))),-L12),0)-M12) -> 97688.393
A13: 46600 | B13: =IF(A13<Assumptions!$B$4,Assumptions!$B$3,Assumptions!$B$5) -> 2000 | C13: 0 | D13: =IF(A13=Assumptions!$B$14,Assumptions!$B$13,IF(AND(A13>Assumptions!$B$14,N(I12)>0.5),Assumptions!$B$18,0)) -> 3062.2692 | E13: =IF(A13=Assumptions!$B$14,Assumptions!$B$10,IF(A13>Assumptions!$B$14,D13-J13,0)) -> 1620.6791 | F13: =IF(A13=Assumptions!$B$25,Assumptions!$B$24,0)+IF(L13>0,PMT(Assumptions!$B$26/12,(Assumptions!$B$27*12+1-((YEAR(A13)-YEAR(Assumptions!$B$33))*12+MONTH(A13)-MONTH(Assumptions!$B$33))),-L13),0) -> 341.66901 | G13: =IF(A13=Assumptions!$B$25,Assumptions!$B$23,0)+IF(L13>0,PMT(Assumptions!$B$26/12,(Assumptions!$B$27*12+1-((YEAR(A13)-YEAR(Assumptions!$B$33))*12+MONTH(A13)-MONTH(Assumptions!$B$33))),-L13),0)-M13 -> 219.55852 | H13: =IF(A13=Assumptions!$B$25,"Condo: OTP + S&P + 25% equity paid",IF(A13=Assumptions!$B$14,"HDB: completion, downpayment paid",IFERROR("Condo: "&INDEX(Assumptions!$A$33:$A$40,MATCH(A13,Assumptions!$B$33:$B$40,0)),""))) | I13: =IF(A13=Assumptions!$B$14,Assumptions!$B$17,IF(A13>Assumptions!$B$14,N(I12)-E13,0)) -> 663728.56 | J13: =IF(A13>Assumptions!$B$14,N(I12)*Assumptions!$B$15/12,0) -> 1441.59 | K13: =SUMIFS(Assumptions!$D$33:$D$40,Assumptions!$B$33:$B$40,A13) -> 0 | L13: =N(N12) -> 97688.393 | M13: =L13*Assumptions!$B$26/12 -> 122.11049 | N13: =L13+K13-(IF(L13>0,PMT(Assumptions!$B$26/12,(Assumptions!$B$27*12+1-((YEAR(A13)-YEAR(Assumptions!$B$33))*12+MONTH(A13)-MONTH(Assumptions!$B$33))),-L13),0)-M13) -> 97468.835
A14: 46631 | B14: =IF(A14<Assumptions!$B$4,Assumptions!$B$3,Assumptions!$B$5) -> 2000 | C14: 0 | D14: =IF(A14=Assumptions!$B$14,Assumptions!$B$13,IF(AND(A14>Assumptions!$B$14,N(I13)>0.5),Assumptions!$B$18,0)) -> 3062.2692 | E14: =IF(A14=Assumptions!$B$14,Assumptions!$B$10,IF(A14>Assumptions!$B$14,D14-J14,0)) -> 1624.1906 | F14: =IF(A14=Assumptions!$B$25,Assumptions!$B$24,0)+IF(L14>0,PMT(Assumptions!$B$26/12,(Assumptions!$B$27*12+1-((YEAR(A14)-YEAR(Assumptions!$B$33))*12+MONTH(A14)-MONTH(Assumptions!$B$33))),-L14),0) -> 341.66901 | G14: =IF(A14=Assumptions!$B$25,Assumptions!$B$23,0)+IF(L14>0,PMT(Assumptions!$B$26/12,(Assumptions!$B$27*12+1-((YEAR(A14)-YEAR(Assumptions!$B$33))*12+MONTH(A14)-MONTH(Assumptions!$B$33))),-L14),0)-M14 -> 219.83297 | H14: =IF(A14=Assumptions!$B$25,"Condo: OTP + S&P + 25% equity paid",IF(A14=Assumptions!$B$14,"HDB: completion, downpayment paid",IFERROR("Condo: "&INDEX(Assumptions!$A$33:$A$40,MATCH(A14,Assumptions!$B$33:$B$40,0)),""))) | I14: =IF(A14=Assumptions!$B$14,Assumptions!$B$17,IF(A14>Assumptions!$B$14,N(I13)-E14,0)) -> 662104.37 | J14: =IF(A14>Assumptions!$B$14,N(I13)*Assumptions!$B$15/12,0) -> 1438.0786 | K14: =SUMIFS(Assumptions!$D$33:$D$40,Assumptions!$B$33:$B$40,A14) -> 0 | L14: =N(N13) -> 97468.835 | M14: =L14*Assumptions!$B$26/12 -> 121.83604 | N14: =L14+K14-(IF(L14>0,PMT(Assumptions!$B$26/12,(Assumptions!$B$27*12+1-((YEAR(A14)-YEAR(Assumptions!$B$33))*12+MONTH(A14)-MONTH(Assumptions!$B$33))),-L14),0)-M14) -> 97249.002
... A102: 49310 | B102: =IF(A102<Assumptions!$B$4,Assumptions!$B$3,Assumptions!$B$5) -> 4500 | C102: 0 | D102: =IF(A102=Assumptions!$B$14,Assumptions!$B$13,IF(AND(A102>Assumptions!$B$14,N(I101)>0.5),Assumptions!$B$18,0)) -> 3062.2692 | E102: =IF(A102=Assumptions!$B$14,Assumptions!$B$10,IF(A102>Assumptions!$B$14,D102-J102,0)) -> 1964.9563 | F102: =IF(A102=Assumptions!$B$25,Assumptions!$B$24,0)+IF(L102>0,PMT(Assumptions!$B$26/12,(Assumptions!$B$27*12+1-((YEAR(A102)-YEAR(Assumptions!$B$33))*12+MONTH(A102)-MONTH(Assumptions!$B$33))),-L102),0) -> 5413.8482 | G102: =IF(A102=Assumptions!$B$25,Assumptions!$B$23,0)+IF(L102>0,PMT(Assumptions!$B$26/12,(Assumptions!$B$27*12+1-((YEAR(A102)-YEAR(Assumptions!$B$33))*12+MONTH(A102)-MONTH(Assumptions!$B$33))),-L102),0)-M102 -> 3888.086 | H102: =IF(A102=Assumptions!$B$25,"Condo: OTP + S&P + 25% equity paid",IF(A102=Assumptions!$B$14,"HDB: completion, downpayment paid",IFERROR("Condo: "&INDEX(Assumptions!$A$33:$A$40,MATCH(A102,Assumptions!$B$33:$B$40,0)),""))) | I102: =IF(A102=Assumptions!$B$14,Assumptions!$B$17,IF(A102>Assumptions!$B$14,N(I101)-E102,0)) -> 504487.13 | J102: =IF(A102>Assumptions!$B$14,N(I101)*Assumptions!$B$15/12,0) -> 1097.3128 | K102: =SUMIFS(Assumptions!$D$33:$D$40,Assumptions!$B$33:$B$40,A102) -> 0 | L102: =N(N101) -> 1220609.7 | M102: =L102*Assumptions!$B$26/12 -> 1525.7622 | N102: =L102+K102-(IF(L102>0,PMT(Assumptions!$B$26/12,(Assumptions!$B$27*12+1-((YEAR(A102)-YEAR(Assumptions!$B$33))*12+MONTH(A102)-MONTH(Assumptions!$B$33))),-L102),0)-M102) -> 1216721.7
A104: Summary
A105: Total outflow (whole period) | B105: =SUM(B3:B102) -> 352500 | D105: =SUM(D3:D102) -> 543577.84 | F105: =SUM(F3:F102) -> 955790.23
A106: Total equity (whole period) | B106: =SUM(C3:C102) -> 0 | D106: =SUM(E3:E102) -> 395512.87 | F106: =SUM(G3:G102) -> 763278.35
A107: Money lost (outflow − equity) | B107: =SUM(B3:B102)-SUM(C3:C102) -> 352500 | D107: =SUM(D3:D102)-SUM(E3:E102) -> 148064.97 | F107: =SUM(F3:F102)-SUM(G3:G102) -> 192511.88
A108: Outflow to Jan 2032 | B108: =SUMIFS(B3:B102,$A$3:$A$102,"<="&DATE(2032,1,1)) -> 190500 | D108: =SUMIFS(D3:D102,$A$3:$A$102,"<="&DATE(2032,1,1)) -> 433336.15 | F108: =SUMIFS(F3:F102,$A$3:$A$102,"<="&DATE(2032,1,1)) -> 760891.69
A109: Equity to Jan 2032 | B109: =SUMIFS(C3:C102,$A$3:$A$102,"<="&DATE(2032,1,1)) -> 0 | D109: =SUMIFS(E3:E102,$A$3:$A$102,"<="&DATE(2032,1,1)) -> 327386.39 | F109: =SUMIFS(G3:G102,$A$3:$A$102,"<="&DATE(2032,1,1)) -> 626322.47
A110: Lost to Jan 2032 | B110: =SUMIFS(B3:B102,$A$3:$A$102,"<="&DATE(2032,1,1))-SUMIFS(C3:C102,$A$3:$A$102,"<="&DATE(2032,1,1)) -> 190500 | D110: =SUMIFS(D3:D102,$A$3:$A$102,"<="&DATE(2032,1,1))-SUMIFS(E3:E102,$A$3:$A$102,"<="&DATE(2032,1,1)) -> 105949.76 | F110: =SUMIFS(F3:F102,$A$3:$A$102,"<="&DATE(2032,1,1))-SUMIFS(G3:G102,$A$3:$A$102,"<="&DATE(2032,1,1)) -> 134569.22
A112: Loan still owed at end | D112: =I102 -> 504487.13 | F112: =N102 -> 1216721.7

Sheet Assumptions
A1: Assumptions (blue = inputs you can change; black = formulas)
A2: Rent
A3: Monthly rent (now to switch date) | B3: 2000 | C3: From you
A4: Rent increase starts | B4: 47484 | C4: From you: higher rent from Jan 2030
A5: Monthly rent (after switch) | B5: 4500 | C5: From you
A7: HDB resale
A8: Purchase price | B8: 900000 | C8: From you
A9: Loan-to-value | B9: 0.75 | C9: HDB loan max 75%
A10: Downpayment (equity) | B10: =B8*(1-B9) -> 225000
A11: Buyer's stamp duty | B11: 21600 | C11: IRAS BSD tiers on $900K
A12: Legal, valuation & misc fees | B12: 3000 | C12: Estimate; not equity
A13: Total cash/CPF out at completion | B13: =B10+B11+B12 -> 249600
A14: Completion (loan drawn) | B14: 46388 | C14: From you: January 2027
A15: Interest rate (HDB concessionary) | B15: 0.026 | C15: HDB rate, Q3 2026
A16: Tenure (years) | B16: 25
A17: Loan amount | B17: =B8*B9 -> 675000
A18: Monthly instalment | B18: =PMT(B15/12,B16*12,-B17) -> 3062.2692 | C18: Starts month after completion
A20: Condo (new launch)
A21: Purchase price | B21: 1980000 | C21: From you
A22: Loan-to-value | B22: 0.75 | C22: Bank loan max 75%
A23: Upfront equity (25%) | B23: =B21*(1-B22) -> 495000 | C23: OTP 5% + S&P 15% + 1st half of foundation 5%
A24: Total upfront cash/CPF out | B24: 565000 | C24: From you: incl. BSD (~$68.6K) & legal
A25: Upfront payment month | B25: 46296 | C25: From you: October 2026
A26: Interest rate (bank, est.) | B26: 0.015 | C26: 2026 bank packages ~1.3–1.8%
A27: Tenure (years, from 1st disbursement) | B27: 30
A28: Loan amount | B28: =B21*B22 -> 1485000
A29: Non-equity upfront costs | B29: =B24-B23 -> 70000
A31: Condo progressive payments funded by the loan (TOP assumed Apr 2029, foundation already laid)
A32: Stage | B32: Est. date | C32: % of price | D32: Loan disbursed
A33: Foundation (balance 5%) | B33: 46388 | C33: 0.05 | D33: =C33*$B$21 -> 99000
A34: Reinforced concrete framework | B34: 46692 | C34: 0.1 | D34: =C34*$B$21 -> 198000
A35: Brick walls | B35: 46844 | C35: 0.05 | D35: =C35*$B$21 -> 99000
A36: Ceiling/roofing | B36: 46966 | C36: 0.05 | D36: =C36*$B$21 -> 99000
A37: Electrical wiring/plumbing/windows | B37: 47058 | C37: 0.05 | D37: =C37*$B$21 -> 99000
A38: Carparks/roads/drains | B38: 47150 | C38: 0.05 | D38: =C38*$B$21 -> 99000
A39: TOP | B39: 47209 | C39: 0.25 | D39: =C39*$B$21 -> 495000
A40: CSC (~12 months after TOP) | B40: 47574 | C40: 0.15 | D40: =C40*$B$21 -> 297000
A41: Total | C41: =SUM(C33:C40) -> 0.75 | D41: =SUM(D33:D40) -> 1485000
A43: Notes
A44: Equity = cash put into the property + principal repaid. No property price appreciation is assumed.
...
